Workbook

Sheet דוח ת"מ
A1: נדרש א
A3: דו"ח תזרים מזומנים לשנה שנסתיימה ב- 31.12.16 חברת "ניידים" בע"מ
A4: ת"מ מפעילות שוטפת | D4: התאמות לרווח ( נספח א' )
D5: הכנסות והוצאות שלא כרוכות בת"מ
A6: הפסד השנה | B6: =ביאורים!D42 -> -17000
A7: התאמות לרווח ( נספח א' ) | B7: =G22 -> 36000 | D7: רווח הון ממכירת השקעה בני"ע | G7: =-ביאורים!B6 -> -5000
A8: מזומנים שנבעו מפעילות שוטפת | B8: =SUM(B6:B7) -> 19000 | D8: רווח מעליית ערך השקעה בני"ע | G8: =-ביאורים!B8 -> -10000
D9: הפסד הון ממכירת רהוט | G9: =-ביאורים!F15 -> 4000
A10: ת"מ מפעילות השקעה | D10: הוצאות פחת רהוט | G10: =ביאורים!D15 -> 20000
A11: תמורה ממכירת השקעה בני"ע סחירים | B11: =-ביאורים!B5 -> 95000 | G11: =SUM(G7:G10) -> 9000
A12: רכישת השקעה בני"ע סחירים | B12: =-ביאורים!B7 -> -102000
A13: תמורה ממכירת רהוט | B13: =ביאורים!F13 -> 10000
A14: מזומנים ששימשו לפעילות השקעה | B14: =SUM(B11:B13) -> 3000 | D14: שינויים בסעיפי רכוש והתחייבות שוטפים
D15: קיטון בזכאים | G15: =ביאורים!B20 -> -4000
D16: קיטון במלאי | G16: 39000
A17: ת"מ מפעילות מימון | D17: גידול בחייבים | G17: -10000
A18: פרעון הלוואה לז"א | B18: =ביאורים!B27 -> -1000 | D18: גידול בהוצאות לשלם | G18: 2000
A19: הנפקת הון מניות במזומן | B19: =ביאורים!B35+ביאורים!D35 -> 25000 | G19: =SUM(G15:G18) -> 27000
A20: דיבידנד ששולם במזומן | B20: =ביאורים!B42+ביאורים!D44 -> -8000
A21: מזומנים שנבעו מפעילות מימון | B21: =SUM(B18:B20) -> 16000
D22: סה"כ התאמות לרווח | G22: =G19+G11 -> 36000
A24: י.ס מזומנים ושווי מזומנים | B24: 84000
A25: י.פ מזומנים ושווי מזומנים | B25: -46000
A26: שינוי במזומנים השנה | B26: =B24+B25 -> 38000 | D26: נספח ב' - פעולות שלא במזומן
D27: דיבידנד לשלם | G27: =ביאורים!B43 -> 3000
D28: רכישת רהוט באשראי זכאים | G28: =ביאורים!B21 -> 31000
D29: הנפקת מניות הטבה | G29: =ביאורים!B36 -> 5000
E31: ניקוד בגין הצגת הדוח עצמו : 8 נקודות
A33: נדרש ב
A34: יחסי נזילות | D34: 2016 | F34: 2015
B36: נכסים שוטפים | E36: 253000 | G36: 222000
A37: יחס שוטף | B37: התחייבויות שוטפות | D37: =E36/E37 -> 2.2192982 | E37: 114000 | F37: =G36/G37 -> 2.5517241 | G37: 87000 | H37: 2
B39: נכסים שוטפים בניכוי מלאי
A40: יחס מהיר | B40: התחייבויות שוטפות | E40: 218000 | G40: 148000
D41: =E40/E41 -> 1.9122807 | E41: 114000 | F41: =G40/G41 -> 1.7011494 | G41: 87000 | H41: 2
A44: נדרש ג
A45: יחסים אלו מודדים את יכולת החברה לפרוע את התחייבויותיה השוטפות באמצעות נכסיה השוטפים, ככל שהיחס גבוה יותר (גבוה מ-1) נזילות החברה גבוהה יותר.
A46: ניתן לומר שע"פ היחס השוטף לחברה יש מספיק נכסים שוטפים בכדי לפרוע את התחייבויותיה השוטפות בתוספת מרווח בטחון של מעל ל- 100%.
A47: על פניו, מדובר ברמת נזילות גבוהה ויחד עם זאת, במצב כזה כדאי לחברה לשקול להשקיע חלק מנכסים השוטפים כהשקעות מניבות לטווח ארוך.

Sheet ביאורים
A1: ביאורים | G1: ניקוד
B3: השקעה בני"ע סחירים
A4: י.פ | B4: 90000
A5: תמורה ממכירה | B5: -95000
A6: רווח הון | B6: 5000
A7: רכישה | B7: 102000 | G7: 4
A8: רווח מעליית ערך | B8: =B9-B7-B6-B5-B4 -> 10000
A9: י.ס | B9: 112000
B12: רהוט - עלות | C12: רהוט - פחת שנצבר | F12: הפסד הון
A13: י.פ | B13: 38000 | C13: י.פ | D13: 10000 | E13: תמורה | F13: =F15-F14 -> 10000
A14: מכירה | B14: =-B13/2 -> -19000 | C14: מכירה | D14: =-D13/2 -> -5000 | E14: עלות מופחתת | F14: =B14-D14 -> -14000 | G14: 6
A15: רכישה באשראי זכאים (P.N) | B15: =B16-B13-B14 -> 31000 | C15: הוצאות פחת P.N | D15: =D16-D14-D13 -> 20000 | E15: הפסד הון | F15: -4000
A16: י.ס | B16: 50000 | C16: י.ס | D16: 25000
B18: זכאים
A19: י.פ | B19: 10000
A20: קיטון בזכאים | B20: =B22-B21-B19 -> -4000
A21: רכישת רכב באשראי | B21: =B15 -> 31000 | G21: 2
A22: י.ס | B22: 37000
B25: הלוואה לז"א
A26: י.פ | B26: 23000
A27: פרעון הלוואה | B27: =B28-B26 -> -1000 | G27: 1
A28: י.ס | B28: 22000
B33: הון מניות | D33: פרמיה על מניות
A34: י.פ | B34: 18000 | C34: י.פ | D34: 42000
A35: הנפקת מניות במזומן | B35: 15000 | C35: הנפקת מניות במזומן | D35: 10000 | G35: 2
A36: הנפקת מניות הטבה | B36: =B37-B35-B34 -> 5000 | C36: הנפקת מניות הטבה | D36: =-B36 -> -5000
A37: י.ס | B37: 38000 | C37: י.ס | D37: =SUM(D34:D36) -> 47000
B40: דיבידנד לשלם | D40: עודפים
A41: י.פ | B41: 5000 | C41: י.פ | D41: 80000
A42: שולם בגין שנה קודמת | B42: =-B41 -> -5000 | C42: הפסד השנה (P.N) | D42: =D45-D44-D43-D41 -> -17000 | G42: 3
A43: הוכרז השנה וטרם שולם | B43: =-D43 -> 3000 | C43: הוכרז ולא שולם | D43: -3000
A44: י.ס | B44: =B43 -> 3000 | C44: הוכרז ושולם | D44: =-3000 -> -3000
C45: י.ס | D45: 57000
G49: =SUM(G3:G46) -> 18

Sheet שאלה 2 - הון עצמי
A1: שאלה 2 - הון עצמי | H1: ניקוד
A3: נדרש א
A5: ח. עו"ש | B5: 140000 | C5: ח. פרמיה | D5: 14000
A6: ז. הון מניות רגילות | B6: 40000 | C6: ז.עו"ש | D6: 14000 | H6: 2
A7: ז. פרמיה | B7: =B5-B6 -> 100000
A9: ח. פרמיה | B9: 44000 | H9: 1
A10: ז. הון מניות רגילות | B10: =B9 -> 44000
A12: ח. עו"ש | B12: 40000
A13: ז.תקבולים ע"ח אופציות | B13: 40000 | H13: 1
A15: ח. עו"ש | B15: =7000*6 -> 42000
A16: ח. תקבולים ע"ח אופציות | B16: =7000*4 -> 28000 | H16: 3
A17: ז. הון מניות | B17: 14000
A18: ז. פרמיה | B18: =B15+B16-B17 -> 56000
A20: ח. קרקע | B20: 200000
A21: ז. הון מניות רגילות | B21: 120000 | H21: 1
A22: ז. פרמיה | B22: =B20-B21 -> 80000
A24: ח.עודפים | B24: 119400 | H24: 1
A25: ז.דיבידנד לשלם | B25: =B24 -> 119400
A28: נדרש ב
A30: פרטים | B30: הון מניות רגילות | C30: פרמיה | D30: עודפים | E30: תקבולים ע"ח אופציות | F30: סה"כ
A31: 1.1.2016 | B31: 180000 | C31: =C40-C37-C36-C34-C33-C32 -> 80000 | D31: 220000 | E31: - | F31: =SUM(B31:E31) -> 480000 | H31: 2
A32: הנפקת מניות | B32: 40000 | C32: =F32-B32 -> 100000 | F32: 140000 | H32: 1
A33: הוצאות הנפקה | C33: =F33 -> -14000 | F33: =-D5 -> -14000 | H33: 1
A34: הנפקת מניות הטבה | B34: =B9 -> 44000 | C34: =-B34 -> -44000 | F34: =SUM(B34:E34) -> 0 | H34: 1
A35: הנפקת אופציות | E35: =B12 -> 40000 | F35: =B13 -> 40000 | H35: 1
A36: מימוש אופציות | B36: =B17 -> 14000 | C36: =B18 -> 56000 | E36: =-B16 -> -28000 | F36: =SUM(B36:E36) -> 42000 | H36: 1
A37: רכישת קרקע כנגד מניות | B37: =B21 -> 120000 | C37: =B22 -> 80000 | F37: =SUM(B37:E37) -> 200000 | H37: 1
A38: רווח השנה | D38: 90000 | F38: =SUM(B38:E38) -> 90000 | H38: 1
A39: דיבידנד שהוכרז | D39: =-B24 -> -119400 | F39: =SUM(B39:E39) -> -119400 | H39: 1
A40: 31.12.2013 | B40: =SUM(B31:B39) -> 398000 | C40: 258000 | D40: =SUM(D31:D39) -> 190600 | E40: =SUM(E31:E39) -> 12000 | F40: =SUM(F31:F39) -> 858600 | H40: 1
A42: נדרש ג
A43: החשב טועה | H43: 2
A44: אין להציג את הדיבידנד שחולק בשנת 2016 במסגרת פעילות השקעה .
A45: כמו שהנפקת מניות (גיוס כספים מבעלי המניות) הינה פעילות מימון, כך גם חלוקת דיבידנד שהיא | H45: 3
A46: למעשה פעולה דומה (אך הפוכה) מהנפקת הון הינה פעולת מימון. יחד עם זאת , במקרה המתואר הדיבידנד רק הוכרז ולא חולק
A47: במזומן ולכן, יש להציג אותו בנספח ב' - פעולות שלא במזומן בדוח ת"מ בשנת 2016
H48: =SUM(H2:H45) -> 25

Sheet שאלה 3 - אגח
B2: שאלה 3 -אג"ח | H2: ניקוד
A3: נדרש א:
A4: קרן | B4: 180000
A5: ריבית נקובה | B5: 0.04
A6: ריבית שוק | B6: 0.07
A8: תאריך | B8: תזרים | C8: מקדם היוון | D8: תזרים מהוון
A9: 31.12.2016 | B9: =+$B$5*$B$4 -> 7200 | C9: =(1+$B$6)^E9 -> 1.07 | D9: =+B9/C9 -> 6728.972 | E9: 1
A10: 31.12.2017 | B10: =+$B$5*$B$4 -> 7200 | C10: =(1+$B$6)^E10 -> 1.1449 | D10: =+B10/C10 -> 6288.7588 | E10: 2
A11: 31.12.2018 | B11: =B10 -> 7200 | C11: =(1+$B$6)^E11 -> 1.225043 | D11: =+B11/C11 -> 5877.3447 | E11: 3
A12: 31.12.2019 | B12: =B11+B4 -> 187200 | C12: =(1+$B$6)^E12 -> 1.310796 | D12: =+B12/C12 -> 142813.98 | E12: 4 | H12: 3
D13: =SUM(D9:D12) -> 161709.06 | E13: סכום הגיוס
A15: פקודת יומן ליום ההנפקה
A17: ח. עו"ש | B17: =D13 -> 161709.06
A18: ח.ניכיון | B18: =-B17+B19 -> 18290.941 | H18: 2
A19: ז.אג"ח | B19: =B4 -> 180000
B21: חובה | C21: זכות
A22: קופה | B22: =+D13 -> 161709.06 | D22: לא נדרש
A23: פרמיה | C23: =B22-C24 -> -18290.941
A24: אג"ח | C24: =+B4 -> 180000
A25: נדרש ב:
B26: י.פ | C26: הוצאות מימון, נטו | D26: הוצאות ריבית | E26: פחת ניכיון | F26: יתרת ניכיון | G26: י.ס.
F27: 18291 | G27: =+B22 -> 161709.06
A28: 31.12.16 | B28: =+G27 -> 161709.06 | C28: =+B28*$B$6 -> 11319.634 | D28: =+B9 -> 7200 | E28: =C28-D28 -> 4119.6341 | F28: =+F27-E28 -> 14171.366 | G28: =B19-F28 -> 165828.63
A29: 31.12.17 | B29: =+G28 -> 165828.63 | C29: =+B29*$B$6 -> 11608.004 | D29: =+B10 -> 7200 | E29: =C29-D29 -> 4408.0044 | F29: =+F28-E29 -> 9763.3615 | G29: =B19-F29 -> 170236.64 | H29: 3
A30: 31.12.18 | B30: =+G29 -> 170236.64 | C30: =+B30*$B$6 -> 11916.565 | D30: =+B11 -> 7200 | E30: =C30-D30 -> 4716.5647 | F30: =+F29-E30 -> 5046.7968 | G30: =B21-F30 -> #VALUE!
A31: 31.12.19 | B31: =+G30 -> #VALUE! | C31: =+B31*$B$6 -> #VALUE! | D31: =+B13 -> 0 | E31: =C31-D31 -> #VALUE! | F31: =+F30-E31 -> #VALUE! | G31: =B22-F31 -> #VALUE!
A32: 31.12.18 | B32: =G29 -> 170236.64 | C32: =+B32*$B$6 -> 11916.565 | D32: =D29 -> 7200 | E32: =C32-D32 -> 4716.5647 | F32: =+F29-E32 -> 5046.7968 | G32: =B19-F32 -> 174953.2
A33: 31.12.19 | B33: =+G32 -> 174953.2 | C33: =+B33*$B$6 -> 12246.724 | D33: =D30 -> 7200 | E33: =C33-D33 -> 5046.7242 | F33: =+F30-E33 -> 0.072541037 | G33: =B19-F33 -> 179999.93
A35: הוצאות מימון לשנת 2017
A36: הוצאות ריבית : | B36: ח. הוצאות ריבית | C36: =D28 -> 7200
B37: ז. הוצאות לשלם | C37: =D29 -> 7200 | H37: 1.5
A39: הוצאות פחת ניכיון : | B39: ח. הוצאות פחת ניכיון | C39: =E29 -> 4408.0044
B40: ז. ניכיון | C40: =C39 -> 4408.0044 | H40: 1.5
A41: נדרש ג :
B42: אג"ח ,נטו ל- 31.12.2017
A43: ערך נקוב | B43: =B4 -> 180000
A44: יתרת ניכיון | B44: =-F29 -> -9763.3615 | H44: 3
A45: אג"ח ,נטו ל- 31.12.2017 | B45: =SUM(B43:B44) -> 170236.64
A47: נדרש ד:
A48: סכום הריבית שתשלם החברה במזומן בשנת 2020 : | C48: 7200 | D48: הוצאות הריבית בגין שנת 2019 משולמות ב - 1.1.2020 | H48: 3
...

Sheet שאלה 4 - שווי מאזני
D1: ניקוד
A2: שאלה 4 - שווי מאזני
A4: נדרש א
A6: אחוז החזקה 25% | B6: 7,000/28,000 =
A8: חישוב הפרש מקורי ליום ה- 1.7.2016
A9: תמורה | B9: 170000
A10: שווי מאזני נרכש | B10: =-180000*0.25 -> -45000 | C10: (130,000+50,000) *25% = | D10: 2
B11: =SUM(B9:B10) -> 125000
A12: ייחוס הפרש מקורי ל -1.7.2016
A13: ציוד | B13: =60000*0.25 -> 15000 | C13: 60,000*25% =
A14: קרקע | B14: =70000*0.25 -> 17500 | C14: 70,000*25% =
A15: מוניטין (P.N) | B15: =B16-B13-B14 -> 92500 | D15: 3
B16: =B11 -> 125000
A18: נדרש ב
A20: תנועה בחשבון השקעה ל- 31.12.2016
A21: תמורה | B21: =B9 -> 170000
A22: חלקי ברווח | B22: =100000*0.25*1/2 -> 12500 | C22: 100,000*1/2* 25%=
A23: פחת הפרש מקורי -ציוד | B23: =-15000/3*0.5 -> -2500 | C23: 15,000 /3* 1/2 = | D23: 6
B24: =SUM(B21:B23) -> 180000 | C24: נותרו 3 שנים מתוך 5
A26: נדרש ג
A27: מכירת 10% מהמניות | B27: 1.1.2017
A29: תמורה | B29: 82000
A30: קיטון בחשבון השקעה | B30: =-B24*10/25 -> -72000 | C30: 180,000 *10/25 = | D30: 3
A31: רווח הון | B31: =SUM(B29:B30) -> 10000
A33: ח. עו"ש | B33: =B29 -> 82000
A34: ז. השקעה ב"פיננסיים" | B34: =-B30 -> 72000 | D34: 2
A35: ז. רווח הון | B35: =B31 -> 10000
A36: נדרש ד
A37: רווח הון כתוצאה ממכירת השקעה מהווה רווח שאינו במזומן ולכן יוצג בנספח א' התאמות לרווח תחת פעילות שוטפת.
A38: רווח ההון יוצג כתזרים שלילי בנספח א' בדוח ת"מ לשנת 2017 בספרי חברת " מחשבונים בע"מ.
D39: 3
C41: סה"כ | D41: =SUM(D3:D40) -> 19
