Workbook

Sheet כותרת
C8: מבחן חשבונאות ב
C9: מועד ב 10.8.2015
C10: סמסטר ב תשעה
I17: 1 | J17: ='שאלה 1 - דוח ת"מ'!E51+'שאלה 1 - ביאורים ת"מ'!G46+'יחסים פיננסיים'!M21 -> 28
I18: 2 | J18: ='שאלה 2 - השקעות'!M74 -> 22
I19: 3 | J19: ='שאלה 3 - ייחוס מיסים'!F22 -> 8
I20: 4 | J20: ='שאלה 4 - הון עצמי'!G48 -> 22
I21: 5 | J21: ='שאלה 5 - אגח'!I56 -> 20
J23: =SUM(J17:J22) -> 100

Sheet שאלה 1 - דוח ת"מ
A1: דו"ח תזרים מזומנים לשנה שנסתיימה ב- 31.12.15 חברת "עינב " בע"מ
E2: ניקוד
A4: ת"מ מפעילות שוטפת
A5: רווח השנה | C5: ='שאלה 1 - ביאורים ת"מ'!D42 -> 99000 | E5: 2
A6: התאמות לרווח ( נספח א' ) | C6: =C45 -> 6000
A7: מזומנים שנבעו מפעילות שוטפת | C7: =SUM(C5:C6) -> 105000
A9: ת"מ מפעילות השקעה | E9: 3
A10: תמורה ממכירת ני"ע סחירים | C10: =-'שאלה 1 - ביאורים ת"מ'!B4 -> 45000
A11: השקעה בניירות ערך סחירים | C11: =-'שאלה 1 - ביאורים ת"מ'!B6 -> -70000
A12: רכישת רכוש קבוע | C12: =-'שאלה 1 - ביאורים ת"מ'!B12 -> -20000
A13: השקעה בחברה כלולה | C13: =-'שאלה 1 - ביאורים ת"מ'!B21 -> -85000
A15: מזומנים ששימשו לפעילות השקעה | C15: =SUM(C10:C13) -> -130000
A18: ת"מ מפעילות מימון | E18: 2
A19: הנפקת אג"ח | C19: ='שאלה 1 - ביאורים ת"מ'!D27 -> 115000
A20: דיבידנד ששולם במזומן השנה | C20: ='שאלה 1 - ביאורים ת"מ'!B42 -> -20000 | F20: =C7+C15+C21 -> 70000
A21: מזומנים שנבעו מפעילות מימון | C21: =SUM(C19:C20) -> 95000
A24: שינוי במזומנים | C24: =C21+C15+C7 -> 70000
A25: י.פ מזומנים ושווי מזומנים | C25: 55000
A26: י.ס. מזומנים ושווי מזומנים | C26: =C24+C25 -> 125000
A29: התאמות לרווח ( נספח א' ) | E29: 2
A30: הכנסות והוצאות שלא כרוכות בת"מ
A31: רווח הון ממכירת ני"ע סחירים | C31: =-'שאלה 1 - ביאורים ת"מ'!B5 -> -15000
A32: ירידת ערך ני"ע סחירים | C32: =-'שאלה 1 - ביאורים ת"מ'!B7 -> 20000
A33: הוצאות פחת רכוש קבוע | C33: ='שאלה 1 - ביאורים ת"מ'!D14 -> 10000
A34: פחת פרמיה | C34: ='שאלה 1 - ביאורים ת"מ'!D28 -> -3000
A35: רווחי אקוויטי | C35: =-'שאלה 1 - ביאורים ת"מ'!B22 -> -30000
C36: =SUM(C31:C35) -> -18000
A38: שינויים בסעיפי רכוש והתחייבות שוטפים
A39: קיטון בלקוחות נטו | C39: 20000
A40: ירידה במלאי | C40: 1000
A41: עליה בזכאים | C41: 34000
A42: קיטון בספקים | C42: -31000
C43: =SUM(C39:C42) -> 24000
A45: סה"כ התאמות לרווח | C45: =C43+C36 -> 6000
A49: נספח ב' - פעולות שלא במזומן | E49: 1
A50: חלוקת הטבה | C50: 10000
D51: סה"כ | E51: =SUM(E5:E50) -> 10

Sheet שאלה 1 - ביאורים ת"מ
A1: ביאורים
B2: השקעה בני"ע סחירים | G2: ניקוד
A3: י.פ | B3: 30000
A4: תמורה ממכירה | B4: -45000
A5: רווח הון ממכירה | B5: 15000 | C5: מחושב
A6: רכישה | B6: 70000 | C6: נתון
A7: הפסד מירידת ערך | B7: -20000 | C7: P.N
A8: י.ס | B8: 50000 | G8: 2
B10: רכוש קבוע - עלות | C10: רכוש קבוע- פחת שנצבר
A11: י.פ | B11: 100000 | C11: י.פ | D11: 40000 | G11: 1
A12: רכישה | B12: 20000
C14: הוצאות פחת P.N | D14: =D15-D11-D13 -> 10000
A15: י.ס | B15: 120000 | C15: י.ס | D15: 50000
B19: השקעה בכלולה
A20: י.פ | B20: 0
A21: השקעה | B21: 85000 | C21: נתון | G21: 1
A22: רווחי אקוויטי | B22: 30000 | C22: P.N | D22: רווחי כלנית : 30000/30%=100,000 | G22: 1
A23: י.ס | B23: =B20+B21+B22 -> 115000
B25: אגח ברוטו | C25: פרמיה | D25: אגח נטו
A26: י.פ. | B26: 0 | C26: 0 | D26: 0
A27: הנפקת אג"ח | B27: 100000 | C27: 15000 | D27: =B27+C27 -> 115000 | G27: 1
A28: הפחתת פרמיה (5 שנים) | B28: 0 | C28: -3000 | D28: =B28+C28 -> -3000
A29: י.ס. | B29: =SUM(B26:B28) -> 100000 | C29: =SUM(C26:C28) -> 12000 | D29: =SUM(D26:D28) -> 112000 | E29: נדרש 1 | G29: 1
A31: יש לתת את מלוא הניקוד גם למי שיציג את טור אגח נטו בלבד (ובלבד שהניתוח נכון כמובן)
B33: הון מניות | D33: פרמיה על מניות
A34: י.פ | B34: 70000 | C34: י.פ | D34: 30000
A35: הנפקת הטבה | B35: 10000 | D35: 0
A36: י.ס | B36: 80000 | C36: י.ס | D36: 30000 | G36: 1
B40: דיבידנד לשלם | D40: עודפים
A41: י.פ | B41: 20000 | C41: י.פ | D41: 148000
A42: שולם בגין שנה קודמת | B42: =-B41 -> -20000 | C42: רווח השנה P.N | D42: =D45-D41+D43-D44 -> 99000 | E42: נדרש 1 | G42: 1
B43: 0
A44: י.ס | B44: 0 | C44: הטבה | D44: -10000 | E44: נדרש 1 | G44: 2
C45: י.ס | D45: 237000
F46: סה"כ : | G46: =SUM(G3:G45) -> 11

Sheet יחסים פיננסיים
M2: ניקוד
A5: נדרש 1:
A6: הטענה אינה נכונה. בדרך כלל ברוב המקרים הטענה אכן נכונה אולם ייתכנו מצבים שונים .
A7: לדוגמא - חברה הנקלעת לקשיים ומוכרת את כל המלאי במחסניה במכירת חיסול תציג תזרים חיובי מפעילותה השוטפת למרות | M7: 3
A8: שמצבה הפיננסי רעוע.
A10: נדרש 2
A11: א. משיכת כספים מחשבון הבנק והגעה למשיכת יתר - תעלה התחייבויות ותקטין יחס שוטף. | M11: 1
A12: ב. גיוס כספים באמצעות הנפקת אג"ח - תגדיל מזומנים והיחס השוטף יעלה. | M12: 1
A13: ג. שערוך חיובי של השקעות שוטפות במניות סחירות המוחזקות לזמן קצר - תגדיל את סעיף השקעות שוטפות והיחס השוטף יעלה | M13: 1
A14: ד. רישום רווחי אקוויטי - לא ישפיע על היחס השוטף - השקעות בחברה כלולה מוצגות במסגרת נכסים בלתי שוטפים. | M14: 1
L21: סה"כ | M21: =SUM(M7:M20) -> 7

Sheet שאלה 2 - השקעות
A1: שאלה 2 - השקעות | M1: ניקוד
A3: חלק א
A5: א
C6: חובה | D6: זכות
A8: 30.9.15 | B8: השקעה | C8: 20000
B9: רווח מעליית ערך | D9: 20000 | M9: 1
A13: ב | D13: רבעון 3 | E13: רבעון 4
B14: הכנסות מימון
B15: רווח מעליית ערך | D15: 20000 | M15: 1
B16: הכנסות מדיבידנד | E16: 72000 | M16: 1
B17: סה"כ הכנסות מימון | D17: =SUM(D15:D16) -> 20000 | E17: =SUM(E15:E16) -> 72000
B19: הוצאות מימון
B20: הפסד מירידת ערך | E20: -10000 | M20: 1
B21: סה"כ הוצאות מימון | D21: =SUM(D20) -> 0 | E21: =SUM(E20) -> -10000
A24: ג | B24: יתרת ההשקעה | D24: 30.9.15 | E24: 31.12.15
D25: 40000 | E25: 30000 | M25: 2
A29: חלק ב
A31: תשובה – הטענה אינה נכונה. רמת הסבירות כי החברה תוכל להפוך את הרווח ("על הנייר") הנובע מהשערוך לרווח במזומן | M31: 4
A32: היא גבוהה מאחר ומדובר בני"ע סחירים שכוונת ההנהלה למכרם במזומן תוך זמן קצר.
A37: חלק ג
A39: א
B40: כל הפתרון באלפי ₪
A41: חישוב התמורה על ידי חישוב ההפרש המקורי / עודף עלות:
D43: אלפי ₪
C44: תמורה | D44: =D45+D46 -> 97500 | M44: 2
B45: חלקי בשווי המאזני | D45: =200000*35% -> 70000 | F45: 200,000*35%=
C46: עודף עלות | D46: =D53 -> 27500 | E46: ע"פ חישוב להלן
A48: ייחוס עודף העלות :
B49: נושא | C49: סה"כ | D49: חלקי | E49: הפחתה לשנה
B50: ציוד | C50: 40000 | D50: =C50*35% -> 14000 | E50: =D50/4 -> 3500 | F50: 14,000/4=
B51: מלאי | C51: 10000 | D51: =C51*35% -> 3500 | E51: =D51/2 -> 1750 | F51: חצי נמכר ולכן הפחתה של חצי
B52: מוניטין נתון | D52: 10000 | E52: אין | M52: 2
D53: =SUM(D50:D52) -> 27500
A55: תנועה בחשבון השקעה
A56: פרטים | B56: השקעה | C56: הון עצמי ב
A57: י.פ. השקעה | B57: =D44 -> 97500 | C57: 200000
A58: הפסד | B58: =C58*35% -> -3500 | C58: -10000
A59: דיבידנד | B59: =C59*45% -> 0 | C59: 0
A60: הפחתת ע.ע. | B60: =-E50-E51 -> -5250 | C60: 0 | F60: בקרה:
A61: י.ס. השקעה | B61: =SUM(B57:B60) -> 88750 | C61: =SUM(C57:C60) -> 190000 | F61: =C61*35%+D53-E50-E51 -> 88750 | M61: 4
...

Sheet שאלה 3 - ייחוס מיסים
F1: ניקוד
A2: שאלה 3 - ייחוס מיסים
A4: דוח התאמה למס הכנסה
A5: רווח לפני מס | B5: 380000
A6: הפרשים תמידיים:
A7: הוצאות אחזקת רכב | B7: 22000 | F7: 1
A8: הוצאות אירוח בארץ | B8: =10000*0.8 -> 8000 | D8: 10,000*80%= | F8: 1
A9: הכנסות פטורות | B9: -20000 | F9: 1
A10: הפרשי עיתוי :
A11: בגין הוצאות פחת ציוד | B11: =B13-B5-B7-B8-B9 -> -20000 | C11: P.N | F11: 2
A13: רווח לצורכי מס | B13: =B15/C14 -> 370000 | F13: 1
C14: 0.21
A15: חבות מיסים | B15: 77700
A18: הוצאות פחת לשנת 2015
B19: בספרים | C19: מ"ה
B20: 30000 | C20: 50000 | F20: 2
B21: נתון
A22: יש להוסיף 20,000 לצורכי מס | E22: סה"כ | F22: =SUM(F2:F21) -> 8
A23: לכן הוצאות פחת לצורכי מ"ה הן 50,000
A24: לכן תקופת ההפחתה לצורך מס היא 3 שנים

Sheet שאלה 4 - הון עצמי
A2: שאלה 4 - הון עצמי | G2: ניקוד
A4: נדרש א +ב'
A6: ח. פרמיה | B6: =B33 -> 100000 | E6: 500,000 *x=100,000 | G6: 5
A7: ז. הון מניות רגילות | B7: 100000 | E7: x=20%
E8: שיעור ההטבה
A9: ח. עו"ש | B9: 48000
A10: ז. תקבולים ע"ח אופציות | B10: 48000 | G10: 1
A12: ח. עו"ש | B12: 32000 | G12: 1
A13: ז. הון מניות רגילות | B13: 20000
A14: ז. פרמיה | B14: =B12-B13 -> 12000
E16: 12,000*70%=8,400
A18: ח. עו"ש | B18: =8400*6 -> 50400 | E18: 8,400*6 =
A19: ח. תקבולים ע"ח אופציות | B19: =8400*4 -> 33600 | E19: 8,400*4 = | G19: 2
A20: ז. הון מניות | B20: =8400*2 -> 16800 | E20: 8,400*1*2 =
A21: ז. פרמיה (P.N) | B21: =B18+B19-B20 -> 67200
A23: ח.עודפים | B23: =-D38 -> 70000 | G23: 1
A24: ז. דיבידנד לשלם | B24: =B23 -> 70000
A26: ח. תקבולים ע"ח אופציות | B26: =12000*0.3*4 -> 14400 | G26: 1
A27: ז. פרמיה | B27: =12000*0.3*4 -> 14400
A29: נדרש ג
A31: פרטים | B31: הון מניות רגילות | C31: פרמיה | D31: עודפים | E31: תקבולים ע"ח אופציות | F31: סה"כ
A32: 1.1.2016 | B32: 500000 | C32: 200000 | D32: 440000 | E32: 0 | F32: =SUM(B32:E32) -> 1140000
A33: הנפקת מניות הטבה | B33: =B40-B35-B36-B32 -> 100000 | C33: =-B33 -> -100000 | F33: =SUM(B33:E33) -> 0 | G33: 1
A34: הנפקת אופציות | E34: =B9 -> 48000 | F34: =SUM(C34:E34) -> 48000 | G34: 1
A35: הנפקת מניות | B35: =B13 -> 20000 | C35: =F35-B35 -> 12000 | F35: 32000 | G35: 1
A36: מימוש אופציות | B36: =B20 -> 16800 | C36: =B21 -> 67200 | E36: =-B19 -> -33600 | F36: =SUM(B36:E36) -> 50400 | G36: 2
A37: הפסד השנה | D37: -110000 | F37: =SUM(B37:E37) -> -110000 | G37: 1
A38: הכרזת דיבידנד (P.N) | D38: -70000 | F38: =SUM(B38:E38) -> -70000 | G38: 1
A39: פקיעת אופציות | C39: =B27 -> 14400 | E39: =-B26 -> -14400 | F39: 0 | G39: 1
A40: 31.12.2016 | B40: 636800 | C40: =SUM(C32:C39) -> 193600 | D40: =SUM(D32:D39) -> 260000 | E40: =SUM(E32:E39) -> 0 | F40: =SUM(F32:F39) -> 1090400
A42: נדרש ד
A44: פקיעת אופציות תזקף בנספח ב' פעולות שלא במזומן מכיוון שמדובר בפעולה מאזנית
A45: שאינה משפיעה על ת"מ של החברה. | G45: 3
F48: סה"כ | G48: =SUM(G2:G46) -> 22

Sheet שאלה 5 - אגח
D2: שאלה 5 -אג"ח | I2: ניקוד
B5: נדרש 1:
B6: קרן | C6: 600000
B7: ריבית נקובה | C7: 0.03
B8: ריבית שוק | C8: 0.05
B10: תאריך | C10: תזרים | D10: מקדם היוון | E10: תזרים מהוון | I10: 3
B11: 31.12.2016 | C11: =+$C$7*$C$6 -> 18000 | D11: =(1+$C$8)^F11 -> 1.05 | E11: =+C11/D11 -> 17142.857 | F11: 1
B12: 31.12.2017 | C12: =+$C$7*$C$6 -> 18000 | D12: =(1+$C$8)^F12 -> 1.1025 | E12: =+C12/D12 -> 16326.531 | F12: 2
B13: 31.12.2018 | C13: =+C12+C6 -> 618000 | D13: =(1+$C$8)^F13 -> 1.157625 | E13: =+C13/D13 -> 533851.64 | F13: 3
E14: =SUM(E11:E13) -> 567321.02 | F14: סכום הגיוס
B16: פקודת יומן ליום ההנפקה
B18: ח. עו"ש | C18: =E14 -> 567321.02
B19: ח. ניכיון | C19: =C20-C18 -> 32678.976 | I19: 3
B20: ז.אג"ח | C20: =C6 -> 600000
C22: חובה | D22: זכות
B23: קופה | C23: =+E14 -> 567321.02 | E23: לא נדרש
B24: פרמיה | D24: =C23-D25 -> -32678.976
B25: אג"ח | D25: =+C6 -> 600000
B27: נדרש 2:
C28: י.פ | D28: הוצאות מימון | E28: הוצאות ריבית | F28: פחת ניכיון | G28: יתרת ניכיון | H28: י.ס.
B29: 2015 | G29: =+D24 -> -32678.976 | H29: =+C23 -> 567321.02
B30: 2016 | C30: =+H29 -> 567321.02 | D30: =+C30*$C$8 -> 28366.051 | E30: =+C11 -> 18000 | F30: =E30-D30 -> -10366.051 | G30: =+G29-F30 -> -22312.925 | H30: =C30-F30 -> 577687.07
B31: 2017 | C31: =+H30 -> 577687.07 | D31: =+C31*$C$8 -> 28884.354 | E31: =+C12 -> 18000 | F31: =E31-D31 -> -10884.354 | G31: =+G30-F31 -> -11428.571 | H31: =C31-F31 -> 588571.43 | I31: 2
B32: 2018 | C32: =+H31 -> 588571.43 | D32: =+C32*$C$8 -> 29428.571 | E32: =+C13 -> 618000 | F32: =E32-D32 -> 588571.43 | G32: =+G31-F32 -> -600000 | H32: =C32-F32 -> 0
B33: 2019 | C33: =+H32 -> 0 | D33: =+C33*$C$8 -> 0 | E33: =+C14 -> 0 | F33: =E33-D33 -> 0 | G33: =+G32-F33 -> -600000 | H33: =C33-F33 -> 0
B34: 2018 | C34: =H31 -> 588571.43 | D34: =+C34*$C$8 -> 29428.571 | E34: =E31 -> 18000 | F34: =E34-D34 -> -11428.571 | G34: =+G33-F34 -> -588571.43 | H34: =C34-F34 -> 600000
C36: ביאור אג"ח ,נטו
B37: ערך נקוב | C37: =C6 -> 600000
B38: יתרת ניכיון | C38: =G31 -> -11428.571 | I38: 3
B39: אג"ח ,נטו ל- 31.12.2017 | C39: =SUM(C37:C38) -> 588571.43
B41: נדרש 3:
B43: הוצאות ריבית | C43: =E30 -> 18000 | I43: 5
B44: פחת ניכיון | C44: =-F31 -> 10884.354
B45: סה"כ הוצאות מימון לשנת 2017 | C45: =SUM(C43:C44) -> 28884.354
B49: נדרש 4
C50: במסגרת תזרים מפעילות שוטפת
B51: הוצאות פחת ניכיון | C51: =-F34 -> 11428.571 | D51: נספח א' בפלוס | I51: 2
B52: הוצאות ריבית | C52: 18000 | D52: חלק מרווח השנה במינוס | I52: 2
H56: סה"כ | I56: =SUM(I4:I55) -> 20

Sheet שאלה 5 - אגח פתרון נוסף
D2: שאלה 5 -אג"ח | I2: ניקוד
B5: נדרש 1:
B6: קרן | C6: 300000
B7: ריבית נקובה | C7: 0.03
B8: ריבית שוק | C8: 0.05
B10: תאריך | C10: תזרים | D10: מקדם היוון | E10: תזרים מהוון | I10: 3
B11: 31.12.2016 | C11: =+$C$7*$C$6 -> 9000 | D11: =(1+$C$8)^F11 -> 1.05 | E11: =+C11/D11 -> 8571.4286 | F11: 1
B12: 31.12.2017 | C12: =+$C$7*$C$6 -> 9000 | D12: =(1+$C$8)^F12 -> 1.1025 | E12: =+C12/D12 -> 8163.2653 | F12: 2
B13: 31.12.2018 | C13: =+C12+C6 -> 309000 | D13: =(1+$C$8)^F13 -> 1.157625 | E13: =+C13/D13 -> 266925.82 | F13: 3
E14: =SUM(E11:E13) -> 283660.51 | F14: סכום הגיוס
B16: פקודת יומן ליום ההנפקה
B18: ח. עו"ש | C18: =E14 -> 283660.51
B19: ח. ניכיון | C19: =C20-C18 -> 16339.488 | I19: 3
B20: ז.אג"ח | C20: =C6 -> 300000
C22: חובה | D22: זכות
B23: קופה | C23: =+E14 -> 283660.51 | E23: לא נדרש
B24: פרמיה | D24: =C23-D25 -> -16339.488
B25: אג"ח | D25: =+C6 -> 300000
B27: נדרש 2:
C28: י.פ | D28: הוצאות מימון | E28: הוצאות ריבית | F28: פחת ניכיון | G28: יתרת ניכיון | H28: י.ס.
B29: 2015 | G29: =+D24 -> -16339.488 | H29: =+C23 -> 283660.51
B30: 2016 | C30: =+H29 -> 283660.51 | D30: =+C30*$C$8 -> 14183.026 | E30: =+C11 -> 9000 | F30: =E30-D30 -> -5183.0256 | G30: =+G29-F30 -> -11156.463 | H30: =C30-F30 -> 288843.54
B31: 2017 | C31: =+H30 -> 288843.54 | D31: =+C31*$C$8 -> 14442.177 | E31: =+C12 -> 9000 | F31: =E31-D31 -> -5442.1769 | G31: =+G30-F31 -> -5714.2857 | H31: =C31-F31 -> 294285.71 | I31: 2
B32: 2018 | C32: =+H31 -> 294285.71 | D32: =+C32*$C$8 -> 14714.286 | E32: =+C13 -> 309000 | F32: =E32-D32 -> 294285.71 | G32: =+G31-F32 -> -300000 | H32: =C32-F32 -> 0
B33: 2019 | C33: =+H32 -> 0 | D33: =+C33*$C$8 -> 0 | E33: =+C14 -> 0 | F33: =E33-D33 -> 0 | G33: =+G32-F33 -> -300000 | H33: =C33-F33 -> 0
B34: 2018 | C34: =H31 -> 294285.71 | D34: =+C34*$C$8 -> 14714.286 | E34: =E31 -> 9000 | F34: =E34-D34 -> -5714.2857 | G34: =+G33-F34 -> -294285.71 | H34: =C34-F34 -> 300000
C36: ביאור אג"ח ,נטו
B37: ערך נקוב | C37: =C6 -> 300000
B38: יתרת ניכיון | C38: =G31 -> -5714.2857 | I38: 3
B39: אג"ח ,נטו ל- 31.12.2017 | C39: =SUM(C37:C38) -> 294285.71
B41: נדרש 3:
B43: הוצאות ריבית | C43: =E30 -> 9000 | I43: 5
B44: פחת ניכיון | C44: =-F31 -> 5442.1769
B45: סה"כ הוצאות מימון לשנת 2017 | C45: =SUM(C43:C44) -> 14442.177
B49: נדרש 4
C50: במסגרת תזרים מפעילות שוטפת
B51: הוצאות פחת ניכיון | C51: =-F34 -> 5714.2857 | D51: נספח א' בפלוס | I51: 2
B52: הוצאות ריבית | C52: =C43 -> 9000 | D52: חלק מרווח השנה במינוס | I52: 2
H56: סה"כ | I56: =SUM(I4:I55) -> 20
