Workbook

Sheet שאלה 1 - דוח ת"מ
A1: שאלה 1 - דוח תזרים מזומנים וניתוח פיננסי
A2: נדרש 1
A3: דו"ח תזרים מזומנים לשנה שנסתיימה ב- 31.12.17 חברת "החיים הטובים" בע"מ
A5: ת"מ מפעילות שוטפת | D5: התאמות לרווח ( נספח א' )
D6: הכנסות והוצאות שלא כרוכות בת"מ
A7: הפסד השנה | B7: =ביאורים!D34 -> -48600
A8: התאמות לרווח ( נספח א' ) | B8: =F21 -> -20400 | D8: רווחי אקוויטי | F8: =ביאורים!B5 -> -26400
A9: מזומנים שנבעו מפעילות שוטפת | B9: =SUM(B7:B8) -> -69000 | D9: הפסד הון ממכירת רהוט | F9: =-ביאורים!F12 -> 2000
D10: הוצאות פחת רהוט | F10: =ביאורים!D12 -> 15000
A11: ת"מ מפעילות השקעה | F11: =SUM(F8:F10) -> -9400
A12: רכישת רהוט במזומן | B12: =-ביאורים!B12 -> -27000
A13: מזומנים ששימשו לפעילות השקעה | B13: =SUM(B12) -> -27000 | D13: שינויים בסעיפי רכוש והתחייבות שוטפים
D14: גידול בזכאים | F14: 15000
D15: גידול בלקוחות | F15: -12000
A16: ת"מ מפעילות מימון | D16: קיטון בהוצאות לשלם | F16: =-14000 -> -14000
A17: קבלת הלוואה לז"א | B17: =ביאורים!B22 -> 20000 | F17: =SUM(F14:F16) -> -11000
A18: הנפקת הון מניות במזומן | B18: =ביאורים!B28+ביאורים!D28 -> 60000
A19: דיבידנד ששולם במזומן | B19: =ביאורים!B34+ביאורים!D35 -> -12000
A20: מזומנים שנבעו מפעילות מימון | B20: =SUM(B17:B19) -> 68000
D21: סה"כ התאמות לרווח | F21: =F17+F11 -> -20400
A23: י.ס מזומנים ושווי מזומנים | B23: 29000 | D23: נספח ב' - פעולות שלא במזומן
A24: י.פ מזומנים ושווי מזומנים | B24: -57000 | D24: מכירת רהוט באשראי חייבים | F24: =ביאורים!B17 -> 9000
A25: שינוי במזומנים השנה | B25: =B23+B24 -> -28000 | D25: הנפקת מניות הטבה | F25: =ביאורים!B27 -> 10000
D26: דיבידנד לשלם | F26: =ביאורים!B35 -> 12000
E29: ניקוד בגין הצגת הדוח | G29: 8
A31: נדרש 2 | G31: ניקוד
A32: יחסי איתנות | C32: שנת 2017 | E32: שנת 2016
C34: 194400 | E34: 203000
A35: יחס ההון העצמי לסך הנכסים | B35: =C34/C35 -> 0.471387 | C35: 412400 | D35: =E34/E35 -> 0.51785714 | E35: 392000 | G35: 2
C37: 218000 | E37: 189000
A38: יחס ההתחייבויות לסך הנכסים | B38: =C37/C38 -> 0.528613 | C38: =C35 -> 412400 | D38: =E37/E38 -> 0.48214286 | E38: 392000 | G38: 2
A41: יחסי האיתנות בוחנים את היחס בין מימון ע"י הון זר למימןן ע"י הון עצמי. ככל שהחברה נשענת יותר על הון עצמי, משמעות הדבר הוא שהיא איתנה יותר
A42: ככל שהיא " נשענת" על הון זר , משמעות הדבר שהיא מגבירה את רמת הסיכון שלה. | G42: 1
A43: ניתן לראות שהחברה מחלקת את הסיכון שלה כמעט שווה בשווה בין ההון העצמי להון הזר שלה, מכיוון שכל היחסים נעים בערך סביב 50%.
A44: כאשר בשנת 2016 נוטה החברה להשען על ההון העצמי שלה קצת יותר מאשר על הון זר.
A45: כמו כן, ניתן לראות מגמה של ירידה באיתנות בשנת 2017 לעומת 2016, מכיוון שבשנת 2017 חל קיטון ביחס ההון העצמי לסך הנכסים מ -52% ל - 47%. | G45: 3
A46: מה שמצביע על כך שהחברה בחרה בשנת 2017 להעזר במימון הון זר על פני הון עצמי.
F47: סה"כ | G47: =SUM(G33:G46) -> 8

Sheet ביאורים
A1: ביאורים | G1: ניקוד
B3: השקעה במוחזקת
A4: י.פ | B4: 145000
A5: חלקי ברווח | B5: =-88000*30% -> -26400 | C5: 88,000 *30%= | G5: 3
A6: י.ס | B6: 171400
B9: רהוט - עלות | C9: רהוט - פחת שנצבר | F9: הפסד הון
A10: י.פ | B10: 92000 | C10: י.פ | D10: 45000 | E10: תמורה באשראי | F10: =-F11+F12 -> 9000
A11: מכירה | B11: -15000 | C11: מכירה | D11: -4000 | E11: עלות מופחתת | F11: =B11-D11 -> -11000
A12: רכישה (P.N) | B12: =B13-B10-B11 -> 27000 | C12: הוצאות פחת ( P.N) | D12: =D13-D10-D11 -> 15000 | E12: הפסד הון | F12: -2000
A13: י.ס | B13: 104000 | C13: י.ס | D13: 56000 | G13: 4
B15: חייבים
A16: י.פ | B16: 80000
A17: מכירת רהוט באשראי | B17: =B18-B16 -> 9000 | G17: 1
A18: י.ס | B18: 89000
B20: הלוואה לז"א
A21: י.פ | B21: 131000
A22: לקיחת הלוואה חדשה | B22: =B23-B21 -> 20000 | G22: 1
A23: י.ס | B23: 151000
B25: הון מניות | D25: פרמיה על מניות
A26: י.פ | B26: 50000 | C26: י.פ | D26: 10000
A27: הנפקת מניות הטבה | B27: 10000 | C27: הנפקת מניות הטבה | D27: =-B27 -> -10000
A28: הנפקת מניות במזומן | B28: 20000 | C28: הנפקת מניות במזומן | D28: =D29-D27-D26 -> 40000 | G28: 4
A29: י.ס | B29: 80000 | C29: י.ס | D29: 40000
B32: דיבידנד לשלם | D32: עודפים
A33: י.פ | B33: 4000 | C33: י.פ | D33: 143000
A34: שולם בגין שנה קודמת | B34: =-B33 -> -4000 | C34: הפסד השנה (P.N) | D34: =D37-D36-D35-D33 -> -48600
A35: הוכרז השנה וטרם שולם | B35: =B36 -> 12000 | C35: הוכרז ושולם | D35: =-8000 -> -8000 | G35: 4
A36: י.ס | B36: 12000 | C36: הוכרז ולא שולם | D36: =-B35 -> -12000
C37: י.ס | D37: 74400
F40: סה"כ | G40: =SUM(G3:G38) -> 17

Sheet שאלה 2 - הון עצמי
A1: שאלה 2 - הון עצמי | I1: ניקוד
A2: נדרש ב
A3: פקודות יומן בנוגע להון עצמי לשנת 2016
A4: ח. עו"ש | B4: =G39 -> 120000
A5: ז. הון מניות רגילות | B5: =B39 -> 100000 | D5: 50,000*2= | I5: 1
A6: ז. פרמיה | B6: =C39 -> 20000
A8: ח. פרמיה | B8: =B4*0.1 -> 12000 | I8: 1
A9: ז.עו"ש | B9: =B8 -> 12000
A11: ח. עו"ש | B11: =F41 -> 100000
A12: ז.תקבולים ע"ח אופציות | B12: =B11 -> 100000 | I12: 1
A14: ח. פרמיה | B14: =B42 -> 160000 | D14: 4000,000*40%=
A15: ז. הון מניות רגילות | B15: =B14 -> 160000 | I15: 1
A17: ח. עודפים | B17: =E43 -> 80000 | I17: 1
A18: ז.קרן הון שמורה | B18: =B17 -> 80000
A20: ח. מחסן/ מבנה | B20: =B44 -> 20000 | I20: 1
A21: ז. הון מניות | B21: =B20 -> 20000 | D21: 10,000*2=
A23: ח. עו"ש | B23: =G45 -> 64000 | D23: 8,000*8=
A24: ח. תקבולים ע"ח אופציות | B24: =-F45 -> 40000 | D24: 8,000*5=
A25: ז. הון מניות | B25: =B45 -> 16000 | D25: 8,000*1*2= | I25: 2
A26: ז. פרמיה | B26: =C45 -> 88000 | D26: P.N
A28: ח. תקבולים ע"ח אופציות | B28: =C47 -> 60000 | I28: 1
A29: ז.פרמיה | B29: =B28 -> 60000
A31: ח.עודפים | B31: =-D48 -> 59600
A32: ז.דיבידנד לשלם | B32: =B31 -> 59600 | F32: 596,000*10%= | I32: 1
A34: נדרש ג
A35: דוח על השינויים בהון העצמי לשנת 2016
D36: נדרש א
A37: פרטים | B37: הון מניות רגילות | C37: פרמיה | D37: עודפים | E37: קרן שמורה | F37: תקבולים ע"ח אופציות | G37: סה"כ
A38: 1.1.2016 | B38: 300000 | C38: 220000 | D38: =D49-D48-D46-D43 -> 130000 | E38: - | F38: - | G38: =SUM(B38:F38) -> 650000 | H38: נדרש א | I38: 2
A39: הנפקת מניות | B39: 100000 | C39: =G39-B39 -> 20000 | G39: 120000 | I39: 1
A40: הוצאות הנפקה | C40: =-G39/10 -> -12000 | G40: =SUM(B40:F40) -> -12000 | I40: 1
A41: הנפקת אופציות | F41: 100000 | G41: =SUM(B41:F41) -> 100000 | I41: 1
A42: הנפקת מניות הטבה | B42: 160000 | C42: =-B42 -> -160000 | G42: =SUM(B42:F42) -> 0 | I42: 1
A43: העברה לקרן שמורה | D43: -80000 | E43: =-D43 -> 80000 | G43: =SUM(B43:F43) -> 0 | I43: 1
A44: הנפקת מניות כנגד מחסן | B44: 20000 | G44: =SUM(B44:F44) -> 20000 | I44: 1
A45: מימוש אופציות | B45: 16000 | C45: 88000 | F45: =-8000*5 -> -40000 | G45: =SUM(B45:F45) -> 64000 | I45: 1
A46: רווח השנה | D46: 215000 | G46: =SUM(B46:F46) -> 215000 | I46: 1
A47: פקיעת אופציות | C47: =-F47 -> 60000 | F47: =-60000 -> -60000 | G47: =SUM(B47:F47) -> 0 | I47: 1
A48: דיבידנד שהוכרז | D48: =-B49*0.1 -> -59600 | G48: =SUM(B48:F48) -> -59600 | I48: 1
A49: 31.12.2016 | B49: =SUM(B38:B48) -> 596000 | C49: =SUM(C38:C48) -> 216000 | D49: 205400 | E49: =SUM(E38:E48) -> 80000 | F49: =SUM(F38:F48) -> 0 | G49: =SUM(B49:F49) -> 1097400 | I49: 1
...

Sheet שאלה 3 - שווי מאזני
A1: שאלה 3 - שווי מאזני
A2: אחוז רכישה | B2: =4.8/12 -> 0.4 | C2: 4,800 /12,000 = | D2: 1
A3: נדרש א
A4: חישוב הפרש מקורי ל - 1.4.16
A5: תמורה | B5: 284000
A6: שווי מאזני נרכש | B6: =-460000*0.4 -> -184000 | C6: 460,000 *40% = | D6: 2
B7: =SUM(B5:B6) -> 100000
A8: ייחוס הפרש מקורי ל - 1.4.16
A9: מכונה | B9: =70000*0.4 -> 28000 | C9: 70,000 *40% =
A10: קרקע | B10: =55000*0.4 -> 22000 | C10: 55,000 *40% =
A11: מוניטין (P.N) | B11: =B12-B10-B9 -> 50000 | D11: 3
B12: =B7 -> 100000
A13: נדרש ב
A14: תנועה בחשבון השקעה ל- 31.12.2016 (רק 9 חודשים)
A15: תמורה | B15: =B5 -> 284000 | D15: 1
A16: חלקי ברווח | B16: =240000/12*9*0.4 -> 72000 | C16: 240,000*9/12* 40%= | D16: 2
A17: חלקי בדיבידנד | B17: =-62000*0.4 -> -24800 | C17: 62,000* 40%= | D17: 1
A18: פחת הפרש מקורי - מכונה | B18: =-28000*0.75/4 -> -5250 | C18: 28,000 *0.75/4 = | D18: 2
B19: =SUM(B15:B18) -> 325950 | C19: נותרו 4 שנים מתוך 9
A20: נדרש ג
A21: רווחי אקוויטי לשנת 2016
A22: חלקי ברווח | B22: =B16 -> 72000
A23: פחת הפרש מקורי | B23: =B18 -> -5250 | D23: 3
B24: =SUM(B22:B23) -> 66750
A25: נדרש ד
A26: מכירת 15% מהמניות | B26: 1.1.2017
A27: תמורה | B27: =B29-B28 -> 100000.25 | C27: P.N
A28: קיטון בחשבון השקעה | B28: =-B19*15/40 -> -122231.25 | C28: 325,950 *15%/40% =
A29: הפסד הון | B29: -22231 | D29: 3
C31: סה"כ | D31: =SUM(D2:D32) -> 18

Sheet שאלה 4 - התחייבויות
B1: שאלה מס 4 - התחייבויות | E1: ניקוד
B3: נדרש א' - פקודת יומן ל - 1.1.17
B4: שיחזור יתרת הפרמיה ליום ההנפקה :
B5: X*5\8=20,000 | E5: 2
B6: X= 32,000
B8: סה"כ תמורה מהנפקה : 382,000 | C8: 350,000+32,000 = | E8: 1
B10: פקודת יומן ליום ההנפקה:
B11: ח. מזומן 382,000
B12: ז. אג"ח 350,000 | E12: 2
B13: ז.פרמיה 32,000
B15: נדרש ב' - הוצאות המימון , נטו לשנת 2017 :
B16: הוצאות ריבית | C16: =350000*0.07 -> 24500 | D16: 350,000*7%= | E16: 1
B17: הכנסות פחת פרמיה | C17: =-32000/8 -> -4000 | D17: 32,000/8 = | E17: 1
B18: הוצאות מימון | C18: =SUM(C16:C17) -> 20500
B20: ח. הוצאות ריבית | C20: =C16 -> 24500
B21: ז.הוצאות לשלם | C21: =C20 -> 24500 | E21: 2
B23: ח. פרמיה | C23: =-C17 -> 4000
B24: ז.הכנסות פחת פרמיה | C24: =C23 -> 4000 | E24: 2
B26: נדרש ג'
B27: יתרת אג"ח נטו במאזן | C27: 31.12.21
B28: ערך נקוב | C28: 350000 | E28: 4
B29: יתרת פרמיה | C29: =32000/8*3 -> 12000 | D29: 32,000/8*3=
B30: אג"ח, נטו | C30: =SUM(C28:C29) -> 362000
B32: נדרש ד'
B33: מנכ"ל החברה צודק | E33: 1
B34: כלכלן החברה טועה | E34: 1
B35: ע"פ עקרון ההקבלה יש להכיר בהוצאות הריבית בשנה שבה התרחשו ללא קשר למועד תשלום הריבית במזומן
B36: לכן, בשנת 2025 לא יזקפו הוצאות מימון בגין האג"ח , למרות שהריבית משולמת במזומן ב - 1.1.2025
B37: וזאת מכיוון שמדובר בריבית בגים 2024 שנזקפה כנוצאה בדוח רווח והפסד של שנת 2024. | E37: 3
C39: סה"כ | E39: =SUM(E2:E37) -> 20
